2021-03-06 00:48:12,392 [ERROR] discord.client: Attempting a reconnect in 0.24s
Traceback (most recent call last):
  File "/usr/lib/python3/dist-packages/aiohttp/connector.py", line 964, in _create_direct_connection
    hosts = await asyncio.shield(self._resolve_host(
  File "/usr/lib/python3/dist-packages/aiohttp/connector.py", line 829, in _resolve_host
    addrs = await \
  File "/usr/lib/python3/dist-packages/aiohttp/resolver.py", line 29, in resolve
    infos = await self._loop.getaddrinfo(
  File "/usr/lib/python3.9/asyncio/base_events.py", line 856, in getaddrinfo
    return await self.run_in_executor(
  File "/usr/lib/python3.9/concurrent/futures/thread.py", line 52, in run
    result = self.fn(*self.args, **self.kwargs)
  File "/usr/lib/python3.9/socket.py", line 953, in getaddrinfo
    for res in _socket.getaddrinfo(host, port, family, type, proto, flags):
socket.gaierror: [Errno -3] Temporary failure in name resolution

The above exception was the direct cause of the following exception:

Traceback (most recent call last):
  File "/home/vdev/.local/lib/python3.9/site-packages/discord/client.py", line 558, in connect
    self.ws = await asyncio.wait_for(coro, timeout=60.0)
  File "/usr/lib/python3.9/asyncio/tasks.py", line 481, in wait_for
    return fut.result()
  File "/home/vdev/.local/lib/python3.9/site-packages/discord/gateway.py", line 305, in from_client
    gateway = gateway or await client.http.get_gateway()
  File "/home/vdev/.local/lib/python3.9/site-packages/discord/http.py", line 917, in get_gateway
    data = await self.request(Route('GET', '/gateway'))
  File "/home/vdev/.local/lib/python3.9/site-packages/discord/http.py", line 185, in request
    async with self.__session.request(method, url, **kwargs) as r:
  File "/usr/lib/python3/dist-packages/aiohttp/client.py", line 1012, in __aenter__
    self._resp = await self._coro
  File "/usr/lib/python3/dist-packages/aiohttp/client.py", line 480, in _request
    conn = await self._connector.connect(
  File "/usr/lib/python3/dist-packages/aiohttp/connector.py", line 523, in connect
    proto = await self._create_connection(req, traces, timeout)
  File "/usr/lib/python3/dist-packages/aiohttp/connector.py", line 858, in _create_connection
    _, proto = await self._create_direct_connection(
  File "/usr/lib/python3/dist-packages/aiohttp/connector.py", line 971, in _create_direct_connection
    raise ClientConnectorError(req.connection_key, exc) from exc
aiohttp.client_exceptions.ClientConnectorError: Cannot connect to host discord.com:443 ssl:default [Temporary failure in name resolution]
2021-03-06 00:48:24,676 [ERROR] discord.client: Attempting a reconnect in 3.51s
Traceback (most recent call last):
  File "/usr/lib/python3/dist-packages/aiohttp/connector.py", line 964, in _create_direct_connection
    hosts = await asyncio.shield(self._resolve_host(
  File "/usr/lib/python3/dist-packages/aiohttp/connector.py", line 829, in _resolve_host
    addrs = await \
  File "/usr/lib/python3/dist-packages/aiohttp/resolver.py", line 29, in resolve
    infos = await self._loop.getaddrinfo(
  File "/usr/lib/python3.9/asyncio/base_events.py", line 856, in getaddrinfo
    return await self.run_in_executor(
  File "/usr/lib/python3.9/concurrent/futures/thread.py", line 52, in run
    result = self.fn(*self.args, **self.kwargs)
  File "/usr/lib/python3.9/socket.py", line 953, in getaddrinfo
    for res in _socket.getaddrinfo(host, port, family, type, proto, flags):
socket.gaierror: [Errno -3] Temporary failure in name resolution

The above exception was the direct cause of the following exception:

Traceback (most recent call last):
  File "/home/vdev/.local/lib/python3.9/site-packages/discord/client.py", line 558, in connect
    self.ws = await asyncio.wait_for(coro, timeout=60.0)
  File "/usr/lib/python3.9/asyncio/tasks.py", line 481, in wait_for
    return fut.result()
  File "/home/vdev/.local/lib/python3.9/site-packages/discord/gateway.py", line 305, in from_client
    gateway = gateway or await client.http.get_gateway()
  File "/home/vdev/.local/lib/python3.9/site-packages/discord/http.py", line 917, in get_gateway
    data = await self.request(Route('GET', '/gateway'))
  File "/home/vdev/.local/lib/python3.9/site-packages/discord/http.py", line 185, in request
    async with self.__session.request(method, url, **kwargs) as r:
  File "/usr/lib/python3/dist-packages/aiohttp/client.py", line 1012, in __aenter__
    self._resp = await self._coro
  File "/usr/lib/python3/dist-packages/aiohttp/client.py", line 480, in _request
    conn = await self._connector.connect(
  File "/usr/lib/python3/dist-packages/aiohttp/connector.py", line 523, in connect
    proto = await self._create_connection(req, traces, timeout)
  File "/usr/lib/python3/dist-packages/aiohttp/connector.py", line 858, in _create_connection
    _, proto = await self._create_direct_connection(
  File "/usr/lib/python3/dist-packages/aiohttp/connector.py", line 971, in _create_direct_connection
    raise ClientConnectorError(req.connection_key, exc) from exc
aiohttp.client_exceptions.ClientConnectorError: Cannot connect to host discord.com:443 ssl:default [Temporary failure in name resolution]
2021-03-06 00:48:28,197 [ERROR] discord.client: Attempting a reconnect in 4.75s
Traceback (most recent call last):
  File "/usr/lib/python3/dist-packages/aiohttp/connector.py", line 964, in _create_direct_connection
    hosts = await asyncio.shield(self._resolve_host(
  File "/usr/lib/python3/dist-packages/aiohttp/connector.py", line 829, in _resolve_host
    addrs = await \
  File "/usr/lib/python3/dist-packages/aiohttp/resolver.py", line 29, in resolve
    infos = await self._loop.getaddrinfo(
  File "/usr/lib/python3.9/asyncio/base_events.py", line 856, in getaddrinfo
    return await self.run_in_executor(
  File "/usr/lib/python3.9/concurrent/futures/thread.py", line 52, in run
    result = self.fn(*self.args, **self.kwargs)
  File "/usr/lib/python3.9/socket.py", line 953, in getaddrinfo
    for res in _socket.getaddrinfo(host, port, family, type, proto, flags):
socket.gaierror: [Errno -3] Temporary failure in name resolution

The above exception was the direct cause of the following exception:

Traceback (most recent call last):
  File "/home/vdev/.local/lib/python3.9/site-packages/discord/client.py", line 558, in connect
    self.ws = await asyncio.wait_for(coro, timeout=60.0)
  File "/usr/lib/python3.9/asyncio/tasks.py", line 481, in wait_for
    return fut.result()
  File "/home/vdev/.local/lib/python3.9/site-packages/discord/gateway.py", line 305, in from_client
    gateway = gateway or await client.http.get_gateway()
  File "/home/vdev/.local/lib/python3.9/site-packages/discord/http.py", line 917, in get_gateway
    data = await self.request(Route('GET', '/gateway'))
  File "/home/vdev/.local/lib/python3.9/site-packages/discord/http.py", line 185, in request
    async with self.__session.request(method, url, **kwargs) as r:
  File "/usr/lib/python3/dist-packages/aiohttp/client.py", line 1012, in __aenter__
    self._resp = await self._coro
  File "/usr/lib/python3/dist-packages/aiohttp/client.py", line 480, in _request
    conn = await self._connector.connect(
  File "/usr/lib/python3/dist-packages/aiohttp/connector.py", line 523, in connect
    proto = await self._create_connection(req, traces, timeout)
  File "/usr/lib/python3/dist-packages/aiohttp/connector.py", line 858, in _create_connection
    _, proto = await self._create_direct_connection(
  File "/usr/lib/python3/dist-packages/aiohttp/connector.py", line 971, in _create_direct_connection
    raise ClientConnectorError(req.connection_key, exc) from exc
aiohttp.client_exceptions.ClientConnectorError: Cannot connect to host discord.com:443 ssl:default [Temporary failure in name resolution]
2021-03-06 00:48:32,962 [ERROR] discord.client: Attempting a reconnect in 12.30s
Traceback (most recent call last):
  File "/usr/lib/python3/dist-packages/aiohttp/connector.py", line 964, in _create_direct_connection
    hosts = await asyncio.shield(self._resolve_host(
  File "/usr/lib/python3/dist-packages/aiohttp/connector.py", line 829, in _resolve_host
    addrs = await \
  File "/usr/lib/python3/dist-packages/aiohttp/resolver.py", line 29, in resolve
    infos = await self._loop.getaddrinfo(
  File "/usr/lib/python3.9/asyncio/base_events.py", line 856, in getaddrinfo
    return await self.run_in_executor(
  File "/usr/lib/python3.9/concurrent/futures/thread.py", line 52, in run
    result = self.fn(*self.args, **self.kwargs)
  File "/usr/lib/python3.9/socket.py", line 953, in getaddrinfo
    for res in _socket.getaddrinfo(host, port, family, type, proto, flags):
socket.gaierror: [Errno -3] Temporary failure in name resolution

The above exception was the direct cause of the following exception:

Traceback (most recent call last):
  File "/home/vdev/.local/lib/python3.9/site-packages/discord/client.py", line 558, in connect
    self.ws = await asyncio.wait_for(coro, timeout=60.0)
  File "/usr/lib/python3.9/asyncio/tasks.py", line 481, in wait_for
    return fut.result()
  File "/home/vdev/.local/lib/python3.9/site-packages/discord/gateway.py", line 305, in from_client
    gateway = gateway or await client.http.get_gateway()
  File "/home/vdev/.local/lib/python3.9/site-packages/discord/http.py", line 917, in get_gateway
    data = await self.request(Route('GET', '/gateway'))
  File "/home/vdev/.local/lib/python3.9/site-packages/discord/http.py", line 185, in request
    async with self.__session.request(method, url, **kwargs) as r:
  File "/usr/lib/python3/dist-packages/aiohttp/client.py", line 1012, in __aenter__
    self._resp = await self._coro
  File "/usr/lib/python3/dist-packages/aiohttp/client.py", line 480, in _request
    conn = await self._connector.connect(
  File "/usr/lib/python3/dist-packages/aiohttp/connector.py", line 523, in connect
    proto = await self._create_connection(req, traces, timeout)
  File "/usr/lib/python3/dist-packages/aiohttp/connector.py", line 858, in _create_connection
    _, proto = await self._create_direct_connection(
  File "/usr/lib/python3/dist-packages/aiohttp/connector.py", line 971, in _create_direct_connection
    raise ClientConnectorError(req.connection_key, exc) from exc
aiohttp.client_exceptions.ClientConnectorError: Cannot connect to host discord.com:443 ssl:default [Temporary failure in name resolution]
2021-03-06 00:48:45,276 [ERROR] discord.client: Attempting a reconnect in 28.91s
Traceback (most recent call last):
  File "/usr/lib/python3/dist-packages/aiohttp/connector.py", line 964, in _create_direct_connection
    hosts = await asyncio.shield(self._resolve_host(
  File "/usr/lib/python3/dist-packages/aiohttp/connector.py", line 829, in _resolve_host
    addrs = await \
  File "/usr/lib/python3/dist-packages/aiohttp/resolver.py", line 29, in resolve
    infos = await self._loop.getaddrinfo(
  File "/usr/lib/python3.9/asyncio/base_events.py", line 856, in getaddrinfo
    return await self.run_in_executor(
  File "/usr/lib/python3.9/concurrent/futures/thread.py", line 52, in run
    result = self.fn(*self.args, **self.kwargs)
  File "/usr/lib/python3.9/socket.py", line 953, in getaddrinfo
    for res in _socket.getaddrinfo(host, port, family, type, proto, flags):
socket.gaierror: [Errno -3] Temporary failure in name resolution

The above exception was the direct cause of the following exception:

Traceback (most recent call last):
  File "/home/vdev/.local/lib/python3.9/site-packages/discord/client.py", line 558, in connect
    self.ws = await asyncio.wait_for(coro, timeout=60.0)
  File "/usr/lib/python3.9/asyncio/tasks.py", line 481, in wait_for
    return fut.result()
  File "/home/vdev/.local/lib/python3.9/site-packages/discord/gateway.py", line 305, in from_client
    gateway = gateway or await client.http.get_gateway()
  File "/home/vdev/.local/lib/python3.9/site-packages/discord/http.py", line 917, in get_gateway
    data = await self.request(Route('GET', '/gateway'))
  File "/home/vdev/.local/lib/python3.9/site-packages/discord/http.py", line 185, in request
    async with self.__session.request(method, url, **kwargs) as r:
  File "/usr/lib/python3/dist-packages/aiohttp/client.py", line 1012, in __aenter__
    self._resp = await self._coro
  File "/usr/lib/python3/dist-packages/aiohttp/client.py", line 480, in _request
    conn = await self._connector.connect(
  File "/usr/lib/python3/dist-packages/aiohttp/connector.py", line 523, in connect
    proto = await self._create_connection(req, traces, timeout)
  File "/usr/lib/python3/dist-packages/aiohttp/connector.py", line 858, in _create_connection
    _, proto = await self._create_direct_connection(
  File "/usr/lib/python3/dist-packages/aiohttp/connector.py", line 971, in _create_direct_connection
    raise ClientConnectorError(req.connection_key, exc) from exc
aiohttp.client_exceptions.ClientConnectorError: Cannot connect to host discord.com:443 ssl:default [Temporary failure in name resolution]
2021-03-06 00:49:14,255 [ERROR] discord.client: Attempting a reconnect in 23.09s
Traceback (most recent call last):
  File "/usr/lib/python3/dist-packages/aiohttp/connector.py", line 964, in _create_direct_connection
    hosts = await asyncio.shield(self._resolve_host(
  File "/usr/lib/python3/dist-packages/aiohttp/connector.py", line 829, in _resolve_host
    addrs = await \
  File "/usr/lib/python3/dist-packages/aiohttp/resolver.py", line 29, in resolve
    infos = await self._loop.getaddrinfo(
  File "/usr/lib/python3.9/asyncio/base_events.py", line 856, in getaddrinfo
    return await self.run_in_executor(
  File "/usr/lib/python3.9/concurrent/futures/thread.py", line 52, in run
    result = self.fn(*self.args, **self.kwargs)
  File "/usr/lib/python3.9/socket.py", line 953, in getaddrinfo
    for res in _socket.getaddrinfo(host, port, family, type, proto, flags):
socket.gaierror: [Errno -3] Temporary failure in name resolution

The above exception was the direct cause of the following exception:

Traceback (most recent call last):
  File "/home/vdev/.local/lib/python3.9/site-packages/discord/client.py", line 558, in connect
    self.ws = await asyncio.wait_for(coro, timeout=60.0)
  File "/usr/lib/python3.9/asyncio/tasks.py", line 481, in wait_for
    return fut.result()
  File "/home/vdev/.local/lib/python3.9/site-packages/discord/gateway.py", line 305, in from_client
    gateway = gateway or await client.http.get_gateway()
  File "/home/vdev/.local/lib/python3.9/site-packages/discord/http.py", line 917, in get_gateway
    data = await self.request(Route('GET', '/gateway'))
  File "/home/vdev/.local/lib/python3.9/site-packages/discord/http.py", line 185, in request
    async with self.__session.request(method, url, **kwargs) as r:
  File "/usr/lib/python3/dist-packages/aiohttp/client.py", line 1012, in __aenter__
    self._resp = await self._coro
  File "/usr/lib/python3/dist-packages/aiohttp/client.py", line 480, in _request
    conn = await self._connector.connect(
  File "/usr/lib/python3/dist-packages/aiohttp/connector.py", line 523, in connect
    proto = await self._create_connection(req, traces, timeout)
  File "/usr/lib/python3/dist-packages/aiohttp/connector.py", line 858, in _create_connection
    _, proto = await self._create_direct_connection(
  File "/usr/lib/python3/dist-packages/aiohttp/connector.py", line 971, in _create_direct_connection
    raise ClientConnectorError(req.connection_key, exc) from exc
aiohttp.client_exceptions.ClientConnectorError: Cannot connect to host discord.com:443 ssl:default [Temporary failure in name resolution]
2021-03-06 00:49:37,379 [ERROR] discord.client: Attempting a reconnect in 113.20s
Traceback (most recent call last):
  File "/usr/lib/python3/dist-packages/aiohttp/connector.py", line 964, in _create_direct_connection
    hosts = await asyncio.shield(self._resolve_host(
  File "/usr/lib/python3/dist-packages/aiohttp/connector.py", line 829, in _resolve_host
    addrs = await \
  File "/usr/lib/python3/dist-packages/aiohttp/resolver.py", line 29, in resolve
    infos = await self._loop.getaddrinfo(
  File "/usr/lib/python3.9/asyncio/base_events.py", line 856, in getaddrinfo
    return await self.run_in_executor(
  File "/usr/lib/python3.9/concurrent/futures/thread.py", line 52, in run
    result = self.fn(*self.args, **self.kwargs)
  File "/usr/lib/python3.9/socket.py", line 953, in getaddrinfo
    for res in _socket.getaddrinfo(host, port, family, type, proto, flags):
socket.gaierror: [Errno -3] Temporary failure in name resolution

The above exception was the direct cause of the following exception:

Traceback (most recent call last):
  File "/home/vdev/.local/lib/python3.9/site-packages/discord/client.py", line 558, in connect
    self.ws = await asyncio.wait_for(coro, timeout=60.0)
  File "/usr/lib/python3.9/asyncio/tasks.py", line 481, in wait_for
    return fut.result()
  File "/home/vdev/.local/lib/python3.9/site-packages/discord/gateway.py", line 305, in from_client
    gateway = gateway or await client.http.get_gateway()
  File "/home/vdev/.local/lib/python3.9/site-packages/discord/http.py", line 917, in get_gateway
    data = await self.request(Route('GET', '/gateway'))
  File "/home/vdev/.local/lib/python3.9/site-packages/discord/http.py", line 185, in request
    async with self.__session.request(method, url, **kwargs) as r:
  File "/usr/lib/python3/dist-packages/aiohttp/client.py", line 1012, in __aenter__
    self._resp = await self._coro
  File "/usr/lib/python3/dist-packages/aiohttp/client.py", line 480, in _request
    conn = await self._connector.connect(
  File "/usr/lib/python3/dist-packages/aiohttp/connector.py", line 523, in connect
    proto = await self._create_connection(req, traces, timeout)
  File "/usr/lib/python3/dist-packages/aiohttp/connector.py", line 858, in _create_connection
    _, proto = await self._create_direct_connection(
  File "/usr/lib/python3/dist-packages/aiohttp/connector.py", line 971, in _create_direct_connection
    raise ClientConnectorError(req.connection_key, exc) from exc
aiohttp.client_exceptions.ClientConnectorError: Cannot connect to host discord.com:443 ssl:default [Temporary failure in name resolution]
2021-03-06 00:51:30,699 [ERROR] discord.client: Attempting a reconnect in 207.52s
Traceback (most recent call last):
  File "/usr/lib/python3/dist-packages/aiohttp/connector.py", line 964, in _create_direct_connection
    hosts = await asyncio.shield(self._resolve_host(
  File "/usr/lib/python3/dist-packages/aiohttp/connector.py", line 829, in _resolve_host
    addrs = await \
  File "/usr/lib/python3/dist-packages/aiohttp/resolver.py", line 29, in resolve
    infos = await self._loop.getaddrinfo(
  File "/usr/lib/python3.9/asyncio/base_events.py", line 856, in getaddrinfo
    return await self.run_in_executor(
  File "/usr/lib/python3.9/concurrent/futures/thread.py", line 52, in run
    result = self.fn(*self.args, **self.kwargs)
  File "/usr/lib/python3.9/socket.py", line 953, in getaddrinfo
    for res in _socket.getaddrinfo(host, port, family, type, proto, flags):
socket.gaierror: [Errno -3] Temporary failure in name resolution

The above exception was the direct cause of the following exception:

Traceback (most recent call last):
  File "/home/vdev/.local/lib/python3.9/site-packages/discord/client.py", line 558, in connect
    self.ws = await asyncio.wait_for(coro, timeout=60.0)
  File "/usr/lib/python3.9/asyncio/tasks.py", line 481, in wait_for
    return fut.result()
  File "/home/vdev/.local/lib/python3.9/site-packages/discord/gateway.py", line 305, in from_client
    gateway = gateway or await client.http.get_gateway()
  File "/home/vdev/.local/lib/python3.9/site-packages/discord/http.py", line 917, in get_gateway
    data = await self.request(Route('GET', '/gateway'))
  File "/home/vdev/.local/lib/python3.9/site-packages/discord/http.py", line 185, in request
    async with self.__session.request(method, url, **kwargs) as r:
  File "/usr/lib/python3/dist-packages/aiohttp/client.py", line 1012, in __aenter__
    self._resp = await self._coro
  File "/usr/lib/python3/dist-packages/aiohttp/client.py", line 480, in _request
    conn = await self._connector.connect(
  File "/usr/lib/python3/dist-packages/aiohttp/connector.py", line 523, in connect
    proto = await self._create_connection(req, traces, timeout)
  File "/usr/lib/python3/dist-packages/aiohttp/connector.py", line 858, in _create_connection
    _, proto = await self._create_direct_connection(
  File "/usr/lib/python3/dist-packages/aiohttp/connector.py", line 971, in _create_direct_connection
    raise ClientConnectorError(req.connection_key, exc) from exc
aiohttp.client_exceptions.ClientConnectorError: Cannot connect to host discord.com:443 ssl:default [Temporary failure in name resolution]
2021-03-06 00:54:58,246 [ERROR] discord.client: Attempting a reconnect in 207.51s
Traceback (most recent call last):
  File "/usr/lib/python3/dist-packages/aiohttp/connector.py", line 964, in _create_direct_connection
    hosts = await asyncio.shield(self._resolve_host(
  File "/usr/lib/python3/dist-packages/aiohttp/connector.py", line 829, in _resolve_host
    addrs = await \
  File "/usr/lib/python3/dist-packages/aiohttp/resolver.py", line 29, in resolve
    infos = await self._loop.getaddrinfo(
  File "/usr/lib/python3.9/asyncio/base_events.py", line 856, in getaddrinfo
    return await self.run_in_executor(
  File "/usr/lib/python3.9/concurrent/futures/thread.py", line 52, in run
    result = self.fn(*self.args, **self.kwargs)
  File "/usr/lib/python3.9/socket.py", line 953, in getaddrinfo
    for res in _socket.getaddrinfo(host, port, family, type, proto, flags):
socket.gaierror: [Errno -3] Temporary failure in name resolution

The above exception was the direct cause of the following exception:

Traceback (most recent call last):
  File "/home/vdev/.local/lib/python3.9/site-packages/discord/client.py", line 558, in connect
    self.ws = await asyncio.wait_for(coro, timeout=60.0)
  File "/usr/lib/python3.9/asyncio/tasks.py", line 481, in wait_for
    return fut.result()
  File "/home/vdev/.local/lib/python3.9/site-packages/discord/gateway.py", line 305, in from_client
    gateway = gateway or await client.http.get_gateway()
  File "/home/vdev/.local/lib/python3.9/site-packages/discord/http.py", line 917, in get_gateway
    data = await self.request(Route('GET', '/gateway'))
  File "/home/vdev/.local/lib/python3.9/site-packages/discord/http.py", line 185, in request
    async with self.__session.request(method, url, **kwargs) as r:
  File "/usr/lib/python3/dist-packages/aiohttp/client.py", line 1012, in __aenter__
    self._resp = await self._coro
  File "/usr/lib/python3/dist-packages/aiohttp/client.py", line 480, in _request
    conn = await self._connector.connect(
  File "/usr/lib/python3/dist-packages/aiohttp/connector.py", line 523, in connect
    proto = await self._create_connection(req, traces, timeout)
  File "/usr/lib/python3/dist-packages/aiohttp/connector.py", line 858, in _create_connection
    _, proto = await self._create_direct_connection(
  File "/usr/lib/python3/dist-packages/aiohttp/connector.py", line 971, in _create_direct_connection
    raise ClientConnectorError(req.connection_key, exc) from exc
aiohttp.client_exceptions.ClientConnectorError: Cannot connect to host discord.com:443 ssl:default [Temporary failure in name resolution]
2021-03-06 00:58:25,916 [ERROR] discord.client: Attempting a reconnect in 349.67s
Traceback (most recent call last):
  File "/usr/lib/python3/dist-packages/aiohttp/connector.py", line 964, in _create_direct_connection
    hosts = await asyncio.shield(self._resolve_host(
  File "/usr/lib/python3/dist-packages/aiohttp/connector.py", line 829, in _resolve_host
    addrs = await \
  File "/usr/lib/python3/dist-packages/aiohttp/resolver.py", line 29, in resolve
    infos = await self._loop.getaddrinfo(
  File "/usr/lib/python3.9/asyncio/base_events.py", line 856, in getaddrinfo
    return await self.run_in_executor(
  File "/usr/lib/python3.9/concurrent/futures/thread.py", line 52, in run
    result = self.fn(*self.args, **self.kwargs)
  File "/usr/lib/python3.9/socket.py", line 953, in getaddrinfo
    for res in _socket.getaddrinfo(host, port, family, type, proto, flags):
socket.gaierror: [Errno -3] Temporary failure in name resolution

The above exception was the direct cause of the following exception:

Traceback (most recent call last):
  File "/home/vdev/.local/lib/python3.9/site-packages/discord/client.py", line 558, in connect
    self.ws = await asyncio.wait_for(coro, timeout=60.0)
  File "/usr/lib/python3.9/asyncio/tasks.py", line 481, in wait_for
    return fut.result()
  File "/home/vdev/.local/lib/python3.9/site-packages/discord/gateway.py", line 305, in from_client
    gateway = gateway or await client.http.get_gateway()
  File "/home/vdev/.local/lib/python3.9/site-packages/discord/http.py", line 917, in get_gateway
    data = await self.request(Route('GET', '/gateway'))
  File "/home/vdev/.local/lib/python3.9/site-packages/discord/http.py", line 185, in request
    async with self.__session.request(method, url, **kwargs) as r:
  File "/usr/lib/python3/dist-packages/aiohttp/client.py", line 1012, in __aenter__
    self._resp = await self._coro
  File "/usr/lib/python3/dist-packages/aiohttp/client.py", line 480, in _request
    conn = await self._connector.connect(
  File "/usr/lib/python3/dist-packages/aiohttp/connector.py", line 523, in connect
    proto = await self._create_connection(req, traces, timeout)
  File "/usr/lib/python3/dist-packages/aiohttp/connector.py", line 858, in _create_connection
    _, proto = await self._create_direct_connection(
  File "/usr/lib/python3/dist-packages/aiohttp/connector.py", line 971, in _create_direct_connection
    raise ClientConnectorError(req.connection_key, exc) from exc
aiohttp.client_exceptions.ClientConnectorError: Cannot connect to host discord.com:443 ssl:default [Temporary failure in name resolution]
2021-03-06 01:04:15,698 [ERROR] discord.client: Attempting a reconnect in 724.76s
Traceback (most recent call last):
  File "/usr/lib/python3/dist-packages/aiohttp/connector.py", line 964, in _create_direct_connection
    hosts = await asyncio.shield(self._resolve_host(
  File "/usr/lib/python3/dist-packages/aiohttp/connector.py", line 829, in _resolve_host
    addrs = await \
  File "/usr/lib/python3/dist-packages/aiohttp/resolver.py", line 29, in resolve
    infos = await self._loop.getaddrinfo(
  File "/usr/lib/python3.9/asyncio/base_events.py", line 856, in getaddrinfo
    return await self.run_in_executor(
  File "/usr/lib/python3.9/concurrent/futures/thread.py", line 52, in run
    result = self.fn(*self.args, **self.kwargs)
  File "/usr/lib/python3.9/socket.py", line 953, in getaddrinfo
    for res in _socket.getaddrinfo(host, port, family, type, proto, flags):
socket.gaierror: [Errno -3] Temporary failure in name resolution

The above exception was the direct cause of the following exception:

Traceback (most recent call last):
  File "/home/vdev/.local/lib/python3.9/site-packages/discord/client.py", line 558, in connect
    self.ws = await asyncio.wait_for(coro, timeout=60.0)
  File "/usr/lib/python3.9/asyncio/tasks.py", line 481, in wait_for
    return fut.result()
  File "/home/vdev/.local/lib/python3.9/site-packages/discord/gateway.py", line 305, in from_client
    gateway = gateway or await client.http.get_gateway()
  File "/home/vdev/.local/lib/python3.9/site-packages/discord/http.py", line 917, in get_gateway
    data = await self.request(Route('GET', '/gateway'))
  File "/home/vdev/.local/lib/python3.9/site-packages/discord/http.py", line 185, in request
    async with self.__session.request(method, url, **kwargs) as r:
  File "/usr/lib/python3/dist-packages/aiohttp/client.py", line 1012, in __aenter__
    self._resp = await self._coro
  File "/usr/lib/python3/dist-packages/aiohttp/client.py", line 480, in _request
    conn = await self._connector.connect(
  File "/usr/lib/python3/dist-packages/aiohttp/connector.py", line 523, in connect
    proto = await self._create_connection(req, traces, timeout)
  File "/usr/lib/python3/dist-packages/aiohttp/connector.py", line 858, in _create_connection
    _, proto = await self._create_direct_connection(
  File "/usr/lib/python3/dist-packages/aiohttp/connector.py", line 971, in _create_direct_connection
    raise ClientConnectorError(req.connection_key, exc) from exc
aiohttp.client_exceptions.ClientConnectorError: Cannot connect to host discord.com:443 ssl:default [Temporary failure in name resolution]
